<?xml version="1.0" encoding="UTF-8"?>
<ticket>
  <assigned-user-id type="integer" nil="true"></assigned-user-id>
  <attachments-count type="integer">0</attachments-count>
  <closed type="boolean">true</closed>
  <created-at type="datetime">2009-01-09T16:38:34+00:00</created-at>
  <creator-id type="integer">37619</creator-id>
  <milestone-due-on type="datetime" nil="true"></milestone-due-on>
  <milestone-id type="integer">9903</milestone-id>
  <number type="integer">1719</number>
  <permalink>activesupporttestingsetupandteardownrun_with_callbacks_and_mocha-does-not-record-exceptions-as-test-errors</permalink>
  <priority type="integer">1030</priority>
  <project-id type="integer">8994</project-id>
  <raw-data type="binary" nil="true" encoding="base64"></raw-data>
  <state>invalid</state>
  <tag>2.2.2 active_support invalid mocha testing</tag>
  <title> ActiveSupport::Testing::SetupAndTeardown::run_with_callbacks_and_mocha does not record Exceptions as test errors</title>
  <updated-at type="datetime">2009-08-09T23:35:34+01:00</updated-at>
  <user-id type="integer">19965</user-id>
  <version type="integer">8</version>
  <user-name>Jos&#233; Valim</user-name>
  <creator-name>Geoff Longman</creator-name>
  <url>http://rails.lighthouseapp.com/projects/8994/tickets/1719</url>
  <milestone-title>2.x</milestone-title>
  <priority-name nil="true"></priority-name>
  <original-body>Rails 2.2.2
mocha gem installed

run this unit test

require &quot;test_helper&quot;
class BugTest &lt; ActiveSupport::TestCase
 def test_bug
   raise Exception, &quot;this should have been a test error but wasn't&quot;
 end
end

&gt;&gt; rake test:units

test/unit/bugtest.rb:5:in `test_bug': this should have been a test error but wasn't (Exception)
	from /Library/Ruby/Gems/1.8/gems/activesupport-2.2.2/lib/active_support/testing/setup_and_teardown.rb:94:in `__send__'
	from /Library/Ruby/Gems/1.8/gems/activesupport-2.2.2/lib/active_support/testing/setup_and_teardown.rb:94:in `run'
	from /System/Library/Frameworks/Ruby.framework/Versions/1.8/usr/lib/ruby/1.8/test/unit/testsuite.rb:34:in `run'
	from /System/Library/Frameworks/Ruby.framework/Versions/1.8/usr/lib/ruby/1.8/test/unit/testsuite.rb:33:in `each'
	from /System/Library/Frameworks/Ruby.framework/Versions/1.8/usr/lib/ruby/1.8/test/unit/testsuite.rb:33:in `run'
	from /System/Library/Frameworks/Ruby.framework/Versions/1.8/usr/lib/ruby/1.8/test/unit/testsuite.rb:34:in `run'
	from /System/Library/Frameworks/Ruby.framework/Versions/1.8/usr/lib/ruby/1.8/test/unit/testsuite.rb:33:in `each'
	from /System/Library/Frameworks/Ruby.framework/Versions/1.8/usr/lib/ruby/1.8/test/unit/testsuite.rb:33:in `run'
	from /System/Library/Frameworks/Ruby.framework/Versions/1.8/usr/lib/ruby/1.8/test/unit/ui/testrunnermediator.rb:46:in `run_suite'
	from /System/Library/Frameworks/Ruby.framework/Versions/1.8/usr/lib/ruby/1.8/test/unit/ui/console/testrunner.rb:67:in `start_mediator'
	from /System/Library/Frameworks/Ruby.framework/Versions/1.8/usr/lib/ruby/1.8/test/unit/ui/console/testrunner.rb:41:in `start'
	from /System/Library/Frameworks/Ruby.framework/Versions/1.8/usr/lib/ruby/1.8/test/unit/ui/testrunnerutilities.rb:29:in `run'
	from /System/Library/Frameworks/Ruby.framework/Versions/1.8/usr/lib/ruby/1.8/test/unit/autorunner.rb:216:in `run'
	from /System/Library/Frameworks/Ruby.framework/Versions/1.8/usr/lib/ruby/1.8/test/unit/autorunner.rb:12:in `run'
	from /System/Library/Frameworks/Ruby.framework/Versions/1.8/usr/lib/ruby/1.8/test/unit.rb:278
	from test/unit/bugtest.rb:4

it appears that run_with_callbacks_and_mocha does not catch Exception (or the Passthrough exceptions) like run_with_callbacks_and_testunit does.

That means any thrown Exception or Subclass of Exception kills the test run, and thus breaks our continuous build.

I'm not in the know about why run_with_callbacks_and_mocha is written this way but it looks like bug to me.</original-body>
  <latest-body>Rails 2.2.2
mocha gem installed

run this unit test

require &quot;test_helper&quot;
class BugTest &lt; ActiveSupport::TestCase
 def test_bug
   raise Exception, &quot;this should have been a test error but wasn't&quot;
 end
end

&gt;&gt; rake test:units

test/unit/bugtest.rb:5:in `test_bug': this should have been a test error but wasn't (Exception)
	from /Library/Ruby/Gems/1.8/gems/activesupport-2.2.2/lib/active_support/testing/setup_and_teardown.rb:94:in `__send__'
	from /Library/Ruby/Gems/1.8/gems/activesupport-2.2.2/lib/active_support/testing/setup_and_teardown.rb:94:in `run'
	from /System/Library/Frameworks/Ruby.framework/Versions/1.8/usr/lib/ruby/1.8/test/unit/testsuite.rb:34:in `run'
	from /System/Library/Frameworks/Ruby.framework/Versions/1.8/usr/lib/ruby/1.8/test/unit/testsuite.rb:33:in `each'
	from /System/Library/Frameworks/Ruby.framework/Versions/1.8/usr/lib/ruby/1.8/test/unit/testsuite.rb:33:in `run'
	from /System/Library/Frameworks/Ruby.framework/Versions/1.8/usr/lib/ruby/1.8/test/unit/testsuite.rb:34:in `run'
	from /System/Library/Frameworks/Ruby.framework/Versions/1.8/usr/lib/ruby/1.8/test/unit/testsuite.rb:33:in `each'
	from /System/Library/Frameworks/Ruby.framework/Versions/1.8/usr/lib/ruby/1.8/test/unit/testsuite.rb:33:in `run'
	from /System/Library/Frameworks/Ruby.framework/Versions/1.8/usr/lib/ruby/1.8/test/unit/ui/testrunnermediator.rb:46:in `run_suite'
	from /System/Library/Frameworks/Ruby.framework/Versions/1.8/usr/lib/ruby/1.8/test/unit/ui/console/testrunner.rb:67:in `start_mediator'
	from /System/Library/Frameworks/Ruby.framework/Versions/1.8/usr/lib/ruby/1.8/test/unit/ui/console/testrunner.rb:41:in `start'
	from /System/Library/Frameworks/Ruby.framework/Versions/1.8/usr/lib/ruby/1.8/test/unit/ui/testrunnerutilities.rb:29:in `run'
	from /System/Library/Frameworks/Ruby.framework/Versions/1.8/usr/lib/ruby/1.8/test/unit/autorunner.rb:216:in `run'
	from /System/Library/Frameworks/Ruby.framework/Versions/1.8/usr/lib/ruby/1.8/test/unit/autorunner.rb:12:in `run'
	from /System/Library/Frameworks/Ruby.framework/Versions/1.8/usr/lib/ruby/1.8/test/unit.rb:278
	from test/unit/bugtest.rb:4

it appears that run_with_callbacks_and_mocha does not catch Exception (or the Passthrough exceptions) like run_with_callbacks_and_testunit does.

That means any thrown Exception or Subclass of Exception kills the test run, and thus breaks our continuous build.

I'm not in the know about why run_with_callbacks_and_mocha is written this way but it looks like bug to me.</latest-body>
  <original-body-html>&lt;div&gt;&lt;p&gt;Rails 2.2.2 mocha gem installed&lt;/p&gt;
&lt;p&gt;run this unit test&lt;/p&gt;
&lt;p&gt;require &quot;test_helper&quot; class BugTest &amp;lt; ActiveSupport::TestCase
def test_bug raise Exception, &quot;this should have been a test error
but wasn't&quot; end end&lt;/p&gt;
&lt;blockquote&gt;
&lt;blockquote&gt;
&lt;p&gt;rake test:units&lt;/p&gt;
&lt;/blockquote&gt;
&lt;/blockquote&gt;
&lt;p&gt;test/unit/bugtest.rb:5:in &lt;code&gt;test_bug': this should have been
a test error but wasn't (Exception)&lt;/code&gt;&lt;/p&gt;
&lt;pre&gt;
&lt;code&gt;from /Library/Ruby/Gems/1.8/gems/activesupport-2.2.2/lib/active_support/testing/setup_and_teardown.rb:94:in `__send__'
from /Library/Ruby/Gems/1.8/gems/activesupport-2.2.2/lib/active_support/testing/setup_and_teardown.rb:94:in `run'
from /System/Library/Frameworks/Ruby.framework/Versions/1.8/usr/lib/ruby/1.8/test/unit/testsuite.rb:34:in `run'
from /System/Library/Frameworks/Ruby.framework/Versions/1.8/usr/lib/ruby/1.8/test/unit/testsuite.rb:33:in `each'
from /System/Library/Frameworks/Ruby.framework/Versions/1.8/usr/lib/ruby/1.8/test/unit/testsuite.rb:33:in `run'
from /System/Library/Frameworks/Ruby.framework/Versions/1.8/usr/lib/ruby/1.8/test/unit/testsuite.rb:34:in `run'
from /System/Library/Frameworks/Ruby.framework/Versions/1.8/usr/lib/ruby/1.8/test/unit/testsuite.rb:33:in `each'
from /System/Library/Frameworks/Ruby.framework/Versions/1.8/usr/lib/ruby/1.8/test/unit/testsuite.rb:33:in `run'
from /System/Library/Frameworks/Ruby.framework/Versions/1.8/usr/lib/ruby/1.8/test/unit/ui/testrunnermediator.rb:46:in `run_suite'
from /System/Library/Frameworks/Ruby.framework/Versions/1.8/usr/lib/ruby/1.8/test/unit/ui/console/testrunner.rb:67:in `start_mediator'
from /System/Library/Frameworks/Ruby.framework/Versions/1.8/usr/lib/ruby/1.8/test/unit/ui/console/testrunner.rb:41:in `start'
from /System/Library/Frameworks/Ruby.framework/Versions/1.8/usr/lib/ruby/1.8/test/unit/ui/testrunnerutilities.rb:29:in `run'
from /System/Library/Frameworks/Ruby.framework/Versions/1.8/usr/lib/ruby/1.8/test/unit/autorunner.rb:216:in `run'
from /System/Library/Frameworks/Ruby.framework/Versions/1.8/usr/lib/ruby/1.8/test/unit/autorunner.rb:12:in `run'
from /System/Library/Frameworks/Ruby.framework/Versions/1.8/usr/lib/ruby/1.8/test/unit.rb:278
from test/unit/bugtest.rb:4
&lt;/code&gt;
&lt;/pre&gt;
&lt;p&gt;it appears that run_with_callbacks_and_mocha does not catch
Exception (or the Passthrough exceptions) like
run_with_callbacks_and_testunit does.&lt;/p&gt;
&lt;p&gt;That means any thrown Exception or Subclass of Exception kills
the test run, and thus breaks our continuous build.&lt;/p&gt;
&lt;p&gt;I'm not in the know about why run_with_callbacks_and_mocha is
written this way but it looks like bug to me.&lt;/p&gt;&lt;/div&gt;</original-body-html>
  <versions type="array">
    <version type="Ticket::Version">
      <assigned-user-id type="integer" nil="true"></assigned-user-id>
      <attachments-count type="integer">0</attachments-count>
      <body>Rails 2.2.2
mocha gem installed

run this unit test

require &quot;test_helper&quot;
class BugTest &lt; ActiveSupport::TestCase
 def test_bug
   raise Exception, &quot;this should have been a test error but wasn't&quot;
 end
end

&gt;&gt; rake test:units

test/unit/bugtest.rb:5:in `test_bug': this should have been a test error but wasn't (Exception)
	from /Library/Ruby/Gems/1.8/gems/activesupport-2.2.2/lib/active_support/testing/setup_and_teardown.rb:94:in `__send__'
	from /Library/Ruby/Gems/1.8/gems/activesupport-2.2.2/lib/active_support/testing/setup_and_teardown.rb:94:in `run'
	from /System/Library/Frameworks/Ruby.framework/Versions/1.8/usr/lib/ruby/1.8/test/unit/testsuite.rb:34:in `run'
	from /System/Library/Frameworks/Ruby.framework/Versions/1.8/usr/lib/ruby/1.8/test/unit/testsuite.rb:33:in `each'
	from /System/Library/Frameworks/Ruby.framework/Versions/1.8/usr/lib/ruby/1.8/test/unit/testsuite.rb:33:in `run'
	from /System/Library/Frameworks/Ruby.framework/Versions/1.8/usr/lib/ruby/1.8/test/unit/testsuite.rb:34:in `run'
	from /System/Library/Frameworks/Ruby.framework/Versions/1.8/usr/lib/ruby/1.8/test/unit/testsuite.rb:33:in `each'
	from /System/Library/Frameworks/Ruby.framework/Versions/1.8/usr/lib/ruby/1.8/test/unit/testsuite.rb:33:in `run'
	from /System/Library/Frameworks/Ruby.framework/Versions/1.8/usr/lib/ruby/1.8/test/unit/ui/testrunnermediator.rb:46:in `run_suite'
	from /System/Library/Frameworks/Ruby.framework/Versions/1.8/usr/lib/ruby/1.8/test/unit/ui/console/testrunner.rb:67:in `start_mediator'
	from /System/Library/Frameworks/Ruby.framework/Versions/1.8/usr/lib/ruby/1.8/test/unit/ui/console/testrunner.rb:41:in `start'
	from /System/Library/Frameworks/Ruby.framework/Versions/1.8/usr/lib/ruby/1.8/test/unit/ui/testrunnerutilities.rb:29:in `run'
	from /System/Library/Frameworks/Ruby.framework/Versions/1.8/usr/lib/ruby/1.8/test/unit/autorunner.rb:216:in `run'
	from /System/Library/Frameworks/Ruby.framework/Versions/1.8/usr/lib/ruby/1.8/test/unit/autorunner.rb:12:in `run'
	from /System/Library/Frameworks/Ruby.framework/Versions/1.8/usr/lib/ruby/1.8/test/unit.rb:278
	from test/unit/bugtest.rb:4

it appears that run_with_callbacks_and_mocha does not catch Exception (or the Passthrough exceptions) like run_with_callbacks_and_testunit does.

That means any thrown Exception or Subclass of Exception kills the test run, and thus breaks our continuous build.

I'm not in the know about why run_with_callbacks_and_mocha is written this way but it looks like bug to me.</body>
      <body-html>&lt;div&gt;&lt;p&gt;Rails 2.2.2 mocha gem installed&lt;/p&gt;
&lt;p&gt;run this unit test&lt;/p&gt;
&lt;p&gt;require &quot;test_helper&quot; class BugTest &amp;lt; ActiveSupport::TestCase
def test_bug raise Exception, &quot;this should have been a test error
but wasn't&quot; end end&lt;/p&gt;
&lt;blockquote&gt;
&lt;blockquote&gt;
&lt;p&gt;rake test:units&lt;/p&gt;
&lt;/blockquote&gt;
&lt;/blockquote&gt;
&lt;p&gt;test/unit/bugtest.rb:5:in &lt;code&gt;test_bug': this should have been
a test error but wasn't (Exception)&lt;/code&gt;&lt;/p&gt;
&lt;pre&gt;
&lt;code&gt;from /Library/Ruby/Gems/1.8/gems/activesupport-2.2.2/lib/active_support/testing/setup_and_teardown.rb:94:in `__send__'
from /Library/Ruby/Gems/1.8/gems/activesupport-2.2.2/lib/active_support/testing/setup_and_teardown.rb:94:in `run'
from /System/Library/Frameworks/Ruby.framework/Versions/1.8/usr/lib/ruby/1.8/test/unit/testsuite.rb:34:in `run'
from /System/Library/Frameworks/Ruby.framework/Versions/1.8/usr/lib/ruby/1.8/test/unit/testsuite.rb:33:in `each'
from /System/Library/Frameworks/Ruby.framework/Versions/1.8/usr/lib/ruby/1.8/test/unit/testsuite.rb:33:in `run'
from /System/Library/Frameworks/Ruby.framework/Versions/1.8/usr/lib/ruby/1.8/test/unit/testsuite.rb:34:in `run'
from /System/Library/Frameworks/Ruby.framework/Versions/1.8/usr/lib/ruby/1.8/test/unit/testsuite.rb:33:in `each'
from /System/Library/Frameworks/Ruby.framework/Versions/1.8/usr/lib/ruby/1.8/test/unit/testsuite.rb:33:in `run'
from /System/Library/Frameworks/Ruby.framework/Versions/1.8/usr/lib/ruby/1.8/test/unit/ui/testrunnermediator.rb:46:in `run_suite'
from /System/Library/Frameworks/Ruby.framework/Versions/1.8/usr/lib/ruby/1.8/test/unit/ui/console/testrunner.rb:67:in `start_mediator'
from /System/Library/Frameworks/Ruby.framework/Versions/1.8/usr/lib/ruby/1.8/test/unit/ui/console/testrunner.rb:41:in `start'
from /System/Library/Frameworks/Ruby.framework/Versions/1.8/usr/lib/ruby/1.8/test/unit/ui/testrunnerutilities.rb:29:in `run'
from /System/Library/Frameworks/Ruby.framework/Versions/1.8/usr/lib/ruby/1.8/test/unit/autorunner.rb:216:in `run'
from /System/Library/Frameworks/Ruby.framework/Versions/1.8/usr/lib/ruby/1.8/test/unit/autorunner.rb:12:in `run'
from /System/Library/Frameworks/Ruby.framework/Versions/1.8/usr/lib/ruby/1.8/test/unit.rb:278
from test/unit/bugtest.rb:4
&lt;/code&gt;
&lt;/pre&gt;
&lt;p&gt;it appears that run_with_callbacks_and_mocha does not catch
Exception (or the Passthrough exceptions) like
run_with_callbacks_and_testunit does.&lt;/p&gt;
&lt;p&gt;That means any thrown Exception or Subclass of Exception kills
the test run, and thus breaks our continuous build.&lt;/p&gt;
&lt;p&gt;I'm not in the know about why run_with_callbacks_and_mocha is
written this way but it looks like bug to me.&lt;/p&gt;&lt;/div&gt;</body-html>
      <closed type="boolean">false</closed>
      <created-at type="datetime">2009-01-09T16:38:34+00:00</created-at>
      <creator-id type="integer">37619</creator-id>
      <diffable-attributes type="yaml">--- {}

</diffable-attributes>
      <milestone-id type="integer">9903</milestone-id>
      <number type="integer">1719</number>
      <permalink>activesupporttestingsetupandteardownrun_with_callbacks_and_mocha-does-not-record-exceptions-as-test-errors</permalink>
      <priority type="integer">0</priority>
      <project-id type="integer">8994</project-id>
      <state>new</state>
      <tag>2.2.2 active_support mocha testing</tag>
      <title> ActiveSupport::Testing::SetupAndTeardown::run_with_callbacks_and_mocha does not record Exceptions as test errors</title>
      <updated-at type="datetime">2009-01-09T16:38:36+00:00</updated-at>
      <user-id type="integer">37619</user-id>
      <version type="integer">1</version>
      <user-name>Geoff Longman</user-name>
      <creator-name>Geoff Longman</creator-name>
      <url>http://rails.lighthouseapp.com/projects/8994/tickets/1719</url>
      <milestone-title>2.x</milestone-title>
      <priority-name nil="true"></priority-name>
    </version>
    <version type="Ticket::Version">
      <assigned-user-id type="integer" nil="true"></assigned-user-id>
      <attachments-count type="integer">0</attachments-count>
      <body>formatting test case...

@@@
require &quot;test_helper&quot;
class BugTest &lt; ActiveSupport::TestCase
 def test_bug
   raise Exception, &quot;this should have been a test error but wasn't&quot;
 end
end

&gt;&gt; rake test:units
@@@</body>
      <body-html>&lt;div&gt;&lt;p&gt;formatting test case...&lt;/p&gt;


&lt;pre&gt;&lt;code&gt;
require &amp;quot;test_helper&amp;quot;
class BugTest &amp;lt; ActiveSupport::TestCase
 def test_bug
   raise Exception, &amp;quot;this should have been a test error but wasn't&amp;quot;
 end
end

&amp;gt;&amp;gt; rake test:units
&lt;/code&gt;&lt;/pre&gt;&lt;/div&gt;</body-html>
      <closed type="boolean">false</closed>
      <created-at type="datetime">2009-01-09T16:41:28+00:00</created-at>
      <creator-id type="integer">37619</creator-id>
      <diffable-attributes type="yaml">--- {}

</diffable-attributes>
      <milestone-id type="integer">9903</milestone-id>
      <number type="integer">1719</number>
      <permalink>activesupporttestingsetupandteardownrun_with_callbacks_and_mocha-does-not-record-exceptions-as-test-errors</permalink>
      <priority type="integer">0</priority>
      <project-id type="integer">8994</project-id>
      <state>new</state>
      <tag>2.2.2 active_support mocha testing</tag>
      <title> ActiveSupport::Testing::SetupAndTeardown::run_with_callbacks_and_mocha does not record Exceptions as test errors</title>
      <updated-at type="datetime">2009-01-09T16:41:33+00:00</updated-at>
      <user-id type="integer">37619</user-id>
      <version type="integer">2</version>
      <user-name>Geoff Longman</user-name>
      <creator-name>Geoff Longman</creator-name>
      <url>http://rails.lighthouseapp.com/projects/8994/tickets/1719</url>
      <milestone-title>2.x</milestone-title>
      <priority-name nil="true"></priority-name>
    </version>
    <version type="Ticket::Version">
      <assigned-user-id type="integer" nil="true"></assigned-user-id>
      <attachments-count type="integer">0</attachments-count>
      <body>I should add that if mocha is not present the problem does not appear.</body>
      <body-html>&lt;div&gt;&lt;p&gt;I should add that if mocha is not present the problem does not
appear.&lt;/p&gt;&lt;/div&gt;</body-html>
      <closed type="boolean">false</closed>
      <created-at type="datetime">2009-01-09T21:05:59+00:00</created-at>
      <creator-id type="integer">37619</creator-id>
      <diffable-attributes type="yaml">--- {}

</diffable-attributes>
      <milestone-id type="integer">9903</milestone-id>
      <number type="integer">1719</number>
      <permalink>activesupporttestingsetupandteardownrun_with_callbacks_and_mocha-does-not-record-exceptions-as-test-errors</permalink>
      <priority type="integer">0</priority>
      <project-id type="integer">8994</project-id>
      <state>new</state>
      <tag>2.2.2 active_support mocha testing</tag>
      <title> ActiveSupport::Testing::SetupAndTeardown::run_with_callbacks_and_mocha does not record Exceptions as test errors</title>
      <updated-at type="datetime">2009-01-09T21:06:00+00:00</updated-at>
      <user-id type="integer">37619</user-id>
      <version type="integer">3</version>
      <user-name>Geoff Longman</user-name>
      <creator-name>Geoff Longman</creator-name>
      <url>http://rails.lighthouseapp.com/projects/8994/tickets/1719</url>
      <milestone-title>2.x</milestone-title>
      <priority-name nil="true"></priority-name>
    </version>
    <version type="Ticket::Version">
      <assigned-user-id type="integer" nil="true"></assigned-user-id>
      <attachments-count type="integer">0</attachments-count>
      <body>Is this still an issue on the edge ?</body>
      <body-html>&lt;div&gt;&lt;p&gt;Is this still an issue on the edge ?&lt;/p&gt;&lt;/div&gt;</body-html>
      <closed type="boolean">true</closed>
      <created-at type="datetime">2009-03-10T12:19:48+00:00</created-at>
      <creator-id type="integer">37619</creator-id>
      <diffable-attributes type="yaml">--- 
:state: new
</diffable-attributes>
      <milestone-id type="integer">9903</milestone-id>
      <number type="integer">1719</number>
      <permalink>activesupporttestingsetupandteardownrun_with_callbacks_and_mocha-does-not-record-exceptions-as-test-errors</permalink>
      <priority type="integer">0</priority>
      <project-id type="integer">8994</project-id>
      <state>stale</state>
      <tag>2.2.2 active_support mocha testing</tag>
      <title> ActiveSupport::Testing::SetupAndTeardown::run_with_callbacks_and_mocha does not record Exceptions as test errors</title>
      <updated-at type="datetime">2009-03-10T12:19:53+00:00</updated-at>
      <user-id type="integer">1366</user-id>
      <version type="integer">4</version>
      <user-name>Pratik</user-name>
      <creator-name>Geoff Longman</creator-name>
      <url>http://rails.lighthouseapp.com/projects/8994/tickets/1719</url>
      <milestone-title>2.x</milestone-title>
      <priority-name nil="true"></priority-name>
    </version>
    <version type="Ticket::Version">
      <assigned-user-id type="integer" nil="true"></assigned-user-id>
      <attachments-count type="integer">0</attachments-count>
      <body></body>
      <body-html></body-html>
      <closed type="boolean">true</closed>
      <created-at type="datetime">2009-08-03T14:30:42+01:00</created-at>
      <creator-id type="integer">37619</creator-id>
      <diffable-attributes type="yaml">--- 
:tag: 2.2.2 active_support mocha testing
</diffable-attributes>
      <milestone-id type="integer">9903</milestone-id>
      <number type="integer">1719</number>
      <permalink>activesupporttestingsetupandteardownrun_with_callbacks_and_mocha-does-not-record-exceptions-as-test-errors</permalink>
      <priority type="integer">0</priority>
      <project-id type="integer">8994</project-id>
      <state>stale</state>
      <tag>2.2.2 active_support bugmash mocha testing</tag>
      <title> ActiveSupport::Testing::SetupAndTeardown::run_with_callbacks_and_mocha does not record Exceptions as test errors</title>
      <updated-at type="datetime">2009-08-03T14:30:46+01:00</updated-at>
      <user-id type="integer">7211</user-id>
      <version type="integer">5</version>
      <user-name>CancelProfileIsBroken</user-name>
      <creator-name>Geoff Longman</creator-name>
      <url>http://rails.lighthouseapp.com/projects/8994/tickets/1719</url>
      <milestone-title>2.x</milestone-title>
      <priority-name nil="true"></priority-name>
    </version>
    <version type="Ticket::Version">
      <assigned-user-id type="integer" nil="true"></assigned-user-id>
      <attachments-count type="integer">0</attachments-count>
      <body>not reproducible in 2-3-stable

created the bug_test.rb file above, and it reproduced a test Error, instead of killing the test run.</body>
      <body-html>&lt;div&gt;&lt;p&gt;not reproducible in 2-3-stable&lt;/p&gt;
&lt;p&gt;created the bug_test.rb file above, and it reproduced a test
Error, instead of killing the test run.&lt;/p&gt;&lt;/div&gt;</body-html>
      <closed type="boolean">true</closed>
      <created-at type="datetime">2009-08-09T05:45:13+01:00</created-at>
      <creator-id type="integer">37619</creator-id>
      <diffable-attributes type="yaml">--- {}

</diffable-attributes>
      <milestone-id type="integer">9903</milestone-id>
      <number type="integer">1719</number>
      <permalink>activesupporttestingsetupandteardownrun_with_callbacks_and_mocha-does-not-record-exceptions-as-test-errors</permalink>
      <priority type="integer">0</priority>
      <project-id type="integer">8994</project-id>
      <state>stale</state>
      <tag>2.2.2 active_support bugmash mocha testing</tag>
      <title> ActiveSupport::Testing::SetupAndTeardown::run_with_callbacks_and_mocha does not record Exceptions as test errors</title>
      <updated-at type="datetime">2009-08-09T05:45:19+01:00</updated-at>
      <user-id type="integer">11504</user-id>
      <version type="integer">6</version>
      <user-name>Arthur Zapparoli</user-name>
      <creator-name>Geoff Longman</creator-name>
      <url>http://rails.lighthouseapp.com/projects/8994/tickets/1719</url>
      <milestone-title>2.x</milestone-title>
      <priority-name nil="true"></priority-name>
    </version>
    <version type="Ticket::Version">
      <assigned-user-id type="integer" nil="true"></assigned-user-id>
      <attachments-count type="integer">0</attachments-count>
      <body>not reproducible

-1 Same as Arthur. I manually tested in a sample app.</body>
      <body-html>&lt;div&gt;&lt;p&gt;not reproducible&lt;/p&gt;
&lt;p&gt;-1 Same as Arthur. I manually tested in a sample app.&lt;/p&gt;&lt;/div&gt;</body-html>
      <closed type="boolean">true</closed>
      <created-at type="datetime">2009-08-09T23:34:38+01:00</created-at>
      <creator-id type="integer">37619</creator-id>
      <diffable-attributes type="yaml">--- 
:tag: 2.2.2 active_support bugmash mocha testing
</diffable-attributes>
      <milestone-id type="integer">9903</milestone-id>
      <number type="integer">1719</number>
      <permalink>activesupporttestingsetupandteardownrun_with_callbacks_and_mocha-does-not-record-exceptions-as-test-errors</permalink>
      <priority type="integer">0</priority>
      <project-id type="integer">8994</project-id>
      <state>stale</state>
      <tag>2.2.2 active_support bugmash invalid mocha testing</tag>
      <title> ActiveSupport::Testing::SetupAndTeardown::run_with_callbacks_and_mocha does not record Exceptions as test errors</title>
      <updated-at type="datetime">2009-08-09T23:34:43+01:00</updated-at>
      <user-id type="integer">65556</user-id>
      <version type="integer">7</version>
      <user-name>Rizwan Reza</user-name>
      <creator-name>Geoff Longman</creator-name>
      <url>http://rails.lighthouseapp.com/projects/8994/tickets/1719</url>
      <milestone-title>2.x</milestone-title>
      <priority-name nil="true"></priority-name>
    </version>
    <version type="Ticket::Version">
      <assigned-user-id type="integer" nil="true"></assigned-user-id>
      <attachments-count type="integer">0</attachments-count>
      <body></body>
      <body-html></body-html>
      <closed type="boolean">true</closed>
      <created-at type="datetime">2009-08-09T23:35:31+01:00</created-at>
      <creator-id type="integer">37619</creator-id>
      <diffable-attributes type="yaml">--- 
:tag: 2.2.2 active_support bugmash invalid mocha testing
:state: stale
</diffable-attributes>
      <milestone-id type="integer">9903</milestone-id>
      <number type="integer">1719</number>
      <permalink>activesupporttestingsetupandteardownrun_with_callbacks_and_mocha-does-not-record-exceptions-as-test-errors</permalink>
      <priority type="integer">0</priority>
      <project-id type="integer">8994</project-id>
      <state>invalid</state>
      <tag>2.2.2 active_support invalid mocha testing</tag>
      <title> ActiveSupport::Testing::SetupAndTeardown::run_with_callbacks_and_mocha does not record Exceptions as test errors</title>
      <updated-at type="datetime">2009-08-09T23:35:34+01:00</updated-at>
      <user-id type="integer">19965</user-id>
      <version type="integer">8</version>
      <user-name>Jos&#233; Valim</user-name>
      <creator-name>Geoff Longman</creator-name>
      <url>http://rails.lighthouseapp.com/projects/8994/tickets/1719</url>
      <milestone-title>2.x</milestone-title>
      <priority-name nil="true"></priority-name>
    </version>
  </versions>
</ticket>
